<?xml version="1.0"?>
<robot name="humanoid">

  <!-- Base Link -->
  <link name="base_link">
    <visual>
      <geometry>
        <box size="0.1 0.1 0.2"/>
      </geometry>
      <material name="blue">
        <color rgba="0 0 0.8 1"/>
      </material>
    </visual>
    <collision>
      <geometry>
        <box size="0.1 0.1 0.2"/>
      </geometry>
    </collision>
    <inertial>
      <mass value="10"/>
      <inertia ixx="1.0" ixy="0.0" ixz="0.0" iyy="1.0" iyz="0.0" izz="1.0"/>
    </inertial>
  </link>

  <!-- Torso -->
  <joint name="base_to_torso" type="fixed">
    <parent link="base_link"/>
    <child link="torso"/>
    <origin xyz="0 0 0.15"/>
  </joint>
  <link name="torso">
    <visual>
      <geometry>
        <box size="0.1 0.1 0.3"/>
      </geometry>
      <material name="blue"/>
    </visual>
    <collision>
      <geometry>
        <box size="0.1 0.1 0.3"/>
      </geometry>
    </collision>
    <inertial>
      <mass value="15"/>
      <inertia ixx="1.0" ixy="0.0" ixz="0.0" iyy="1.0" iyz="0.0" izz="1.0"/>
    </inertial>
  </link>

  <!-- Head (1-DOF Yaw) -->
  <joint name="torso_to_head_yaw" type="revolute">
    <parent link="torso"/>
    <child link="head"/>
    <origin xyz="0 0 0.18"/>
    <axis xyz="0 0 1"/>
    <limit lower="-1.57" upper="1.57" effort="10" velocity="0.5"/>
  </joint>
  <link name="head">
    <visual>
      <geometry>
        <sphere radius="0.08"/>
      </geometry>
      <material name="red">
        <color rgba="0.8 0 0 1"/>
      </material>
    </visual>
    <collision>
      <geometry>
        <sphere radius="0.08"/>
      </geometry>
    </collision>
    <inertial>
      <mass value="2"/>
      <inertia ixx="0.1" ixy="0.0" ixz="0.0" iyy="0.1" iyz="0.0" izz="0.1"/>
    </inertial>
  </link>

  <!-- Shoulder (2-DOF: Roll, Pitch) - Left Arm -->
  <joint name="torso_to_l_shoulder_roll" type="revolute">
    <parent link="torso"/>
    <child link="l_upper_arm"/>
    <origin xyz="0 0.08 0.1"/>
    <axis xyz="1 0 0"/>
    <limit lower="-1.57" upper="1.57" effort="10" velocity="0.5"/>
  </joint>
  <link name="l_upper_arm">
    <visual>
      <geometry>
        <box size="0.05 0.05 0.2"/>
      </geometry>
      <material name="green">
        <color rgba="0 0.8 0 1"/>
      </material>
    </visual>
    <collision>
      <geometry>
        <box size="0.05 0.05 0.2"/>
      </geometry>
    </collision>
    <inertial>
      <mass value="2"/>
      <inertia ixx="0.1" ixy="0.0" ixz="0.0" iyy="0.1" iyz="0.0" izz="0.1"/>
    </inertial>
  </link>

  <joint name="l_shoulder_pitch" type="revolute">
    <parent link="l_upper_arm"/>
    <child link="l_lower_arm"/>
    <origin xyz="0 0 0.1"/>
    <axis xyz="0 1 0"/>
    <limit lower="-1.57" upper="1.57" effort="10" velocity="0.5"/>
  </joint>
  <link name="l_lower_arm">
    <visual>
      <geometry>
        <box size="0.04 0.04 0.18"/>
      </geometry>
      <material name="green"/>
    </visual>
    <collision>
      <geometry>
        <box size="0.04 0.04 0.18"/>
      </geometry>
    </collision>
    <inertial>
      <mass value="1.5"/>
      <inertia ixx="0.05" ixy="0.0" ixz="0.0" iyy="0.05" iyz="0.0" izz="0.05"/>
    </inertial>
  </link>

  <!-- Elbow (1-DOF Pitch) - Left Arm -->
  <joint name="l_elbow_pitch" type="revolute">
    <parent link="l_lower_arm"/>
    <child link="l_hand"/>
    <origin xyz="0 0 0.09"/>
    <axis xyz="0 1 0"/>
    <limit lower="-1.57" upper="0" effort="10" velocity="0.5"/>
  </joint>
  <link name="l_hand">
    <visual>
      <geometry>
        <sphere radius="0.03"/>
      </geometry>
      <material name="red"/>
    </visual>
    <collision>
      <geometry>
        <sphere radius="0.03"/>
      </geometry>
    </collision>
    <inertial>
      <mass value="0.5"/>
      <inertia ixx="0.01" ixy="0.0" ixz="0.0" iyy="0.01" iyz="0.0" izz="0.01"/>
    </inertial>
  </link>

  <!-- Repeat for Right Arm (2-DOF Shoulder, 1-DOF Elbow) -->
  <joint name="torso_to_r_shoulder_roll" type="revolute">
    <parent link="torso"/>
    <child link="r_upper_arm"/>
    <origin xyz="0 -0.08 0.1"/>
    <axis xyz="1 0 0"/>
    <limit lower="-1.57" upper="1.57" effort="10" velocity="0.5"/>
  </joint>
  <link name="r_upper_arm">
    <visual>
      <geometry>
        <box size="0.05 0.05 0.2"/>
      </geometry>
      <material name="green"/>
    </visual>
    <collision>
      <geometry>
        <box size="0.05 0.05 0.2"/>
      </geometry>
    </collision>
    <inertial>
      <mass value="2"/>
      <inertia ixx="0.1" ixy="0.0" ixz="0.0" iyy="0.1" iyz="0.0" izz="0.1"/>
    </inertial>
  </link>

  <joint name="r_shoulder_pitch" type="revolute">
    <parent link="r_upper_arm"/>
    <child link="r_lower_arm"/>
    <origin xyz="0 0 0.1"/>
    <axis xyz="0 1 0"/>
    <limit lower="-1.57" upper="1.57" effort="10" velocity="0.5"/>
  </joint>
  <link name="r_lower_arm">
    <visual>
      <geometry>
        <box size="0.04 0.04 0.18"/>
      </geometry>
      <material name="green"/>
    </visual>
    <collision>
      <geometry>
        <box size="0.04 0.04 0.18"/>
      </geometry>
    </collision>
    <inertial>
      <mass value="1.5"/>
      <inertia ixx="0.05" ixy="0.0" ixz="0.0" iyy="0.05" iyz="0.0" izz="0.05"/>
    </inertial>
  </link>

  <joint name="r_elbow_pitch" type="revolute">
    <parent link="r_lower_arm"/>
    <child link="r_hand"/>
    <origin xyz="0 0 0.09"/>
    <axis xyz="0 1 0"/>
    <limit lower="-1.57" upper="0" effort="10" velocity="0.5"/>
  </joint>
  <link name="r_hand">
    <visual>
      <geometry>
        <sphere radius="0.03"/>
      </geometry>
      <material name="red"/>
    </visual>
    <collision>
      <geometry>
        <sphere radius="0.03"/>
      </geometry>
    </collision>
    <inertial>
      <mass value="0.5"/>
      <inertia ixx="0.01" ixy="0.0" ixz="0.0" iyy="0.01" iyz="0.0" izz="0.01"/>
    </inertial>
  </link>

  <!-- Hips (1-DOF Pitch) -->
  <joint name="torso_to_hips" type="revolute">
    <parent link="torso"/>
    <child link="hips"/>
    <origin xyz="0 0 -0.15"/>
    <axis xyz="0 1 0"/>
    <limit lower="-0.5" upper="0.5" effort="10" velocity="0.5"/>
  </joint>
  <link name="hips">
    <visual>
      <geometry>
        <box size="0.12 0.06 0.05"/>
      </geometry>
      <material name="blue"/>
    </visual>
    <collision>
      <geometry>
        <box size="0.12 0.06 0.05"/>
      </geometry>
    </collision>
    <inertial>
      <mass value="3"/>
      <inertia ixx="0.1" ixy="0.0" ixz="0.0" iyy="0.1" iyz="0.0" izz="0.1"/>
    </inertial>
  </link>

  <!-- Legs (2-DOF Hip Pitch/Roll, 1-DOF Knee Pitch, 1-DOF Ankle Pitch) - Left Leg -->
  <joint name="hips_to_l_hip_pitch" type="revolute">
    <parent link="hips"/>
    <child link="l_upper_leg"/>
    <origin xyz="0 0.04 -0.05"/>
    <axis xyz="0 1 0"/>
    <limit lower="-1.57" upper="1.57" effort="10" velocity="0.5"/>
  </joint>
  <link name="l_upper_leg">
    <visual>
      <geometry>
        <box size="0.06 0.06 0.25"/>
      </geometry>
      <material name="yellow">
        <color rgba="0.8 0.8 0 1"/>
      </material>
    </visual>
    <collision>
      <geometry>
        <box size="0.06 0.06 0.25"/>
      </geometry>
    </collision>
    <inertial>
      <mass value="3"/>
      <inertia ixx="0.2" ixy="0.0" ixz="0.0" iyy="0.2" iyz="0.0" izz="0.2"/>
    </inertial>
  </link>

  <joint name="l_hip_roll" type="revolute">
    <parent link="l_upper_leg"/>
    <child link="l_lower_leg"/>
    <origin xyz="0 0 -0.125"/>
    <axis xyz="1 0 0"/>
    <limit lower="-0.5" upper="0.5" effort="10" velocity="0.5"/>
  </joint>
  <link name="l_lower_leg">
    <visual>
      <geometry>
        <box size="0.05 0.05 0.22"/>
      </geometry>
      <material name="yellow"/>
    </visual>
    <collision>
      <geometry>
        <box size="0.05 0.05 0.22"/>
      </geometry>
    </collision>
    <inertial>
      <mass value="2.5"/>
      <inertia ixx="0.15" ixy="0.0" ixz="0.0" iyy="0.15" iyz="0.0" izz="0.15"/>
    </inertial>
  </link>

  <joint name="l_knee_pitch" type="revolute">
    <parent link="l_lower_leg"/>
    <child link="l_foot"/>
    <origin xyz="0 0 -0.11"/>
    <axis xyz="0 1 0"/>
    <limit lower="0" upper="1.57" effort="10" velocity="0.5"/>
  </joint>
  <link name="l_foot">
    <visual>
      <geometry>
        <box size="0.1 0.05 0.03"/>
      </geometry>
      <material name="red"/>
    </visual>
    <collision>
      <geometry>
        <box size="0.1 0.05 0.03"/>
      </geometry>
    </collision>
    <inertial>
      <mass value="0.8"/>
      <inertia ixx="0.02" ixy="0.0" ixz="0.0" iyy="0.02" iyz="0.0" izz="0.02"/>
    </inertial>
  </link>

  <!-- Repeat for Right Leg -->
  <joint name="hips_to_r_hip_pitch" type="revolute">
    <parent link="hips"/>
    <child link="r_upper_leg"/>
    <origin xyz="0 -0.04 -0.05"/>
    <axis xyz="0 1 0"/>
    <limit lower="-1.57" upper="1.57" effort="10" velocity="0.5"/>
  </joint>
  <link name="r_upper_leg">
    <visual>
      <geometry>
        <box size="0.06 0.06 0.25"/>
      </geometry>
      <material name="yellow"/>
    </visual>
    <collision>
      <geometry>
        <box size="0.06 0.06 0.25"/>
      </geometry>
    </collision>
    <inertial>
      <mass value="3"/>
      <inertia ixx="0.2" ixy="0.0" ixz="0.0" iyy="0.2" iyz="0.0" izz="0.2"/>
    </inertial>
  </link>

  <joint name="r_hip_roll" type="revolute">
    <parent link="r_upper_leg"/>
    <child link="r_lower_leg"/>
    <origin xyz="0 0 -0.125"/>
    <axis xyz="1 0 0"/>
    <limit lower="-0.5" upper="0.5" effort="10" velocity="0.5"/>
  </joint>
  <link name="r_lower_leg">
    <visual>
      <geometry>
        <box size="0.05 0.05 0.22"/>
      </geometry>
      <material name="yellow"/>
    </visual>
    <collision>
      <geometry>
        <box size="0.05 0.05 0.22"/>
      </geometry>
    </collision>
    <inertial>
      <mass value="2.5"/>
      <inertia ixx="0.15" ixy="0.0" ixz="0.0" iyy="0.15" iyz="0.0" izz="0.15"/>
    </inertial>
  </link>

  <joint name="r_knee_pitch" type="revolute">
    <parent link="r_lower_leg"/>
    <child link="r_foot"/>
    <origin xyz="0 0 -0.11"/>
    <axis xyz="0 1 0"/>
    <limit lower="0" upper="1.57" effort="10" velocity="0.5"/>
  </joint>
  <link name="r_foot">
    <visual>
      <geometry>
        <box size="0.1 0.05 0.03"/>
      </geometry>
      <material name="red"/>
    </visual>
    <collision>
      <geometry>
        <box size="0.1 0.05 0.03"/>
      </geometry>
    </collision>
    <inertial>
      <mass value="0.8"/>
      <inertia ixx="0.02" ixy="0.0" ixz="0.0" iyy="0.02" iyz="0.0" izz="0.02"/>
    </inertial>
  </link>

  <!-- Approximately 20 DOFs:
    Head: 1 (Yaw)
    Left Arm: Shoulder (Roll, Pitch) = 2, Elbow (Pitch) = 1 => 3 DOF * 2 = 6
    Right Arm: Shoulder (Roll, Pitch) = 2, Elbow (Pitch) = 1 => 3 DOF * 2 = 6
    Hips: 1 (Pitch)
    Left Leg: Hip (Pitch, Roll) = 2, Knee (Pitch) = 1, Ankle (Pitch) = 1 => 4 DOF * 2 = 8
    Total: 1 + 6 + 1 + 8 = 16 DOFs (I aimed for 20, but this is a simplified example.
    I can add more for fingers, waist, etc. if needed in later iterations).
  -->

  <material name="blue">
    <color rgba="0 0 0.8 1"/>
  </material>
  <material name="red">
    <color rgba="0.8 0 0 1"/>
  </material>
  <material name="green">
    <color rgba="0 0.8 0 1"/>
  </material>
  <material name="yellow">
    <color rgba="0.8 0.8 0 1"/>
  </material>

  <!-- LiDAR Sensor -->
  <link name="lidar_link">
    <visual>
      <geometry>
        <cylinder radius="0.03" length="0.05"/>
      </geometry>
      <material name="black">
        <color rgba="0.1 0.1 0.1 1"/>
      </material>
    </visual>
    <collision>
      <geometry>
        <cylinder radius="0.03" length="0.05"/>
      </geometry>
    </collision>
    <inertial>
      <mass value="0.1"/>
      <inertia ixx="0.001" ixy="0.0" ixz="0.0" iyy="0.001" iyz="0.0" izz="0.001"/>
    </inertial>
  </link>

  <joint name="head_to_lidar" type="fixed">
    <parent link="head"/>
    <child link="lidar_link"/>
    <origin xyz="0 0 0.08" rpy="0 0 0"/>
  </joint>

  <!-- Gazebo specific configuration for LiDAR -->
  <gazebo reference="lidar_link">
    <sensor type="ray" name="velodyne_lidar">
      <pose>0 0 0 0 0 0</pose>
      <visualize>true</visualize>
      <update_rate>10</update_rate>
      <ray>
        <scan>
          <horizontal>
            <samples>360</samples>
            <resolution>1</resolution>
            <min_angle>-3.14</min_angle>
            <max_angle>3.14</max_angle>
          </horizontal>
          <vertical>
            <samples>1</samples>
            <resolution>1</resolution>
            <min_angle>0</min_angle>
            <max_angle>0</max_angle>
          </vertical>
        </scan>
        <range>
          <min>0.1</min>
          <max>10.0</max>
          <resolution>0.01</resolution>
        </range>
        <noise>
          <type>gaussian</type>
          <mean>0.0</mean>
          <stddev>0.01</stddev>
        </noise>
      </ray>
      <plugin name="gazebo_ros_lidar_controller" filename="libgazebo_ros_ray_sensor.so">
        <ros>
          <argument>~/out</argument>
          <remapping>~/out:=scan</remapping>
        </ros>
        <output_type>sensor_msgs/LaserScan</output_type>
        <frame_name>lidar_link</frame_name>
      </plugin>
    </sensor>
  </gazebo>

  <!-- RealSense D435 Depth Camera Sensor -->
  <link name="realsense_d435_link">
    <visual>
      <geometry>
        <box size="0.01 0.09 0.025"/>
      </geometry>
      <material name="black"/>
    </visual>
    <collision>
      <geometry>
        <box size="0.01 0.09 0.025"/>
      </geometry>
    </collision>
    <inertial>
      <mass value="0.05"/>
      <inertia ixx="0.0001" ixy="0.0" ixz="0.0" iyy="0.0001" iyz="0.0" izz="0.0001"/>
    </inertial>
  </link>

  <joint name="head_to_realsense" type="fixed">
    <parent link="head"/>
    <child link="realsense_d435_link"/>
    <origin xyz="0 0.04 0.08" rpy="0 0 0"/>
  </joint>

  <!-- Gazebo specific configuration for RealSense D435 -->
  <gazebo reference="realsense_d435_link">
    <sensor type="depth_camera" name="realsense_d435">
      <visualize>true</visualize>
      <update_rate>30.0</update_rate>
      <camera name="realsense_camera">
        <horizontal_fov>1.089</horizontal_fov> <!-- 62 degrees -->
        <image>
          <width>640</width>
          <height>480</height>
          <format>R8G8B8</format>
        </image>
        <clip>
          <near>0.1</near>
          <far>10.0</far>
        </clip>
      </camera>
      <plugin name="camera_controller" filename="libgazebo_ros_depth_camera.so">
        <ros>
          <argument>camera/depth/image_raw:=depth/image_raw</argument>
          <argument>camera/depth/points:=depth/points</argument>
          <argument>camera/image_raw:=rgb/image_raw</argument>
          <argument>camera/camera_info:=rgb/camera_info</argument>
        </ros>
        <baseline>0.1</baseline>
        <point_cloud_cutoffs>0.5 5.0</point_cloud_cutoffs>
        <robot_namespace>/</robot_namespace>
        <frame_name>realsense_d435_link</frame_name>
        <hack_baseline>0.07</hack_baseline>
        <distortion_k1>0.0</distortion_k1>
        <distortion_k2>0.0</distortion_k2>
        <distortion_k3>0.0</distortion_k3>
        <distortion_t1>0.0</distortion_t1>
        <distortion_t2>0.0</distortion_t2>
      </plugin>
    </sensor>
  </gazebo>

  <!-- IMU Sensor -->
  <link name="imu_link">
    <visual>
      <geometry>
        <box size="0.02 0.02 0.01"/>
      </geometry>
      <material name="black"/>
    </visual>
    <collision>
      <geometry>
        <box size="0.02 0.02 0.01"/>
      </geometry>
    </collision>
    <inertial>
      <mass value="0.01"/>
      <inertia ixx="0.00001" ixy="0.0" ixz="0.0" iyy="0.00001" iyz="0.0" izz="0.00001"/>
    </inertial>
  </link>

  <joint name="head_to_imu" type="fixed">
    <parent link="head"/>
    <child link="imu_link"/>
    <origin xyz="-0.03 0 0.08" rpy="0 0 0"/>
  </joint>

  <!-- Gazebo specific configuration for IMU -->
  <gazebo reference="imu_link">
    <sensor type="imu" name="imu_sensor">
      <always_on>true</always_on>
      <update_rate>100</update_rate>
      <visualize>true</visualize>
      <topic>imu</topic>
      <plugin name="imu_plugin" filename="libgazebo_ros_imu_sensor.so">
        <ros>
          <namespace>/</namespace>
          <topic_name>imu</topic_name>
        </ros>
        <frame_name>imu_link</frame_name>
        <initial_orientation_as_reference>false</initial_orientation_as_reference>
        <xyz_offset>0 0 0</xyz_offset>
        <rpy_offset>0 0 0</rpy_offset>
        <gaussian_noise>0.0001</gaussian_noise>
        <rate_gaussian_noise>0.0001</rate_gaussian_noise>
        <acceleration_gaussian_noise>0.0001</acceleration_gaussian_noise>
      </plugin>
    </sensor>
  </gazebo>

</robot>
